2020-03-30 03:48:55,863 ERROR: Exception on /auth/login [POST] [in /home/osboxes/PycharmProjects/microblog/venv/lib/python3.6/site-packages/flask/app.py:1891]
Traceback (most recent call last):
  File "/home/osboxes/PycharmProjects/microblog/venv/lib/python3.6/site-packages/sqlalchemy/engine/base.py", line 1246, in _execute_context
    cursor, statement, parameters, context
  File "/home/osboxes/PycharmProjects/microblog/venv/lib/python3.6/site-packages/sqlalchemy/engine/default.py", line 588, in do_execute
    cursor.execute(statement, parameters)
sqlite3.OperationalError: no such table: user

The above exception was the direct cause of the following exception:

Traceback (most recent call last):
  File "/home/osboxes/PycharmProjects/microblog/venv/lib/python3.6/site-packages/flask/app.py", line 2446, in wsgi_app
    response = self.full_dispatch_request()
  File "/home/osboxes/PycharmProjects/microblog/venv/lib/python3.6/site-packages/flask/app.py", line 1951, in full_dispatch_request
    rv = self.handle_user_exception(e)
  File "/home/osboxes/PycharmProjects/microblog/venv/lib/python3.6/site-packages/flask/app.py", line 1820, in handle_user_exception
    reraise(exc_type, exc_value, tb)
  File "/home/osboxes/PycharmProjects/microblog/venv/lib/python3.6/site-packages/flask/_compat.py", line 39, in reraise
    raise value
  File "/home/osboxes/PycharmProjects/microblog/venv/lib/python3.6/site-packages/flask/app.py", line 1949, in full_dispatch_request
    rv = self.dispatch_request()
  File "/home/osboxes/PycharmProjects/microblog/venv/lib/python3.6/site-packages/flask/app.py", line 1935, in dispatch_request
    return self.view_functions[rule.endpoint](**req.view_args)
  File "/home/osboxes/PycharmProjects/microblog/app/auth/routes.py", line 19, in login
    user = User.query.filter_by(username=form.username.data).first()
  File "/home/osboxes/PycharmProjects/microblog/venv/lib/python3.6/site-packages/sqlalchemy/orm/query.py", line 3287, in first
    ret = list(self[0:1])
  File "/home/osboxes/PycharmProjects/microblog/venv/lib/python3.6/site-packages/sqlalchemy/orm/query.py", line 3065, in __getitem__
    return list(res)
  File "/home/osboxes/PycharmProjects/microblog/venv/lib/python3.6/site-packages/sqlalchemy/orm/query.py", line 3389, in __iter__
    return self._execute_and_instances(context)
  File "/home/osboxes/PycharmProjects/microblog/venv/lib/python3.6/site-packages/sqlalchemy/orm/query.py", line 3414, in _execute_and_instances
    result = conn.execute(querycontext.statement, self._params)
  File "/home/osboxes/PycharmProjects/microblog/venv/lib/python3.6/site-packages/sqlalchemy/engine/base.py", line 982, in execute
    return meth(self, multiparams, params)
  File "/home/osboxes/PycharmProjects/microblog/venv/lib/python3.6/site-packages/sqlalchemy/sql/elements.py", line 293, in _execute_on_connection
    return connection._execute_clauseelement(self, multiparams, params)
  File "/home/osboxes/PycharmProjects/microblog/venv/lib/python3.6/site-packages/sqlalchemy/engine/base.py", line 1101, in _execute_clauseelement
    distilled_params,
  File "/home/osboxes/PycharmProjects/microblog/venv/lib/python3.6/site-packages/sqlalchemy/engine/base.py", line 1250, in _execute_context
    e, statement, parameters, cursor, context
  File "/home/osboxes/PycharmProjects/microblog/venv/lib/python3.6/site-packages/sqlalchemy/engine/base.py", line 1476, in _handle_dbapi_exception
    util.raise_from_cause(sqlalchemy_exception, exc_info)
  File "/home/osboxes/PycharmProjects/microblog/venv/lib/python3.6/site-packages/sqlalchemy/util/compat.py", line 398, in raise_from_cause
    reraise(type(exception), exception, tb=exc_tb, cause=cause)
  File "/home/osboxes/PycharmProjects/microblog/venv/lib/python3.6/site-packages/sqlalchemy/util/compat.py", line 152, in reraise
    raise value.with_traceback(tb)
  File "/home/osboxes/PycharmProjects/microblog/venv/lib/python3.6/site-packages/sqlalchemy/engine/base.py", line 1246, in _execute_context
    cursor, statement, parameters, context
  File "/home/osboxes/PycharmProjects/microblog/venv/lib/python3.6/site-packages/sqlalchemy/engine/default.py", line 588, in do_execute
    cursor.execute(statement, parameters)
sqlalchemy.exc.OperationalError: (sqlite3.OperationalError) no such table: user
[SQL: SELECT user.id AS user_id, user.username AS user_username, user.email AS user_email, user.password_hash AS user_password_hash, user.about_me AS user_about_me, user.last_seen AS user_last_seen 
FROM user 
WHERE user.username = ?
 LIMIT ? OFFSET ?]
[parameters: ('12345', 1, 0)]
(Background on this error at: http://sqlalche.me/e/e3q8)
2020-03-30 04:01:01,320 INFO: Microblog startup [in /home/osboxes/PycharmProjects/microblog/app/__init__.py:74]
2020-03-30 04:23:48,264 INFO: Microblog startup [in /home/osboxes/PycharmProjects/microblog/app/__init__.py:74]
