2020-04-30 09:44:28,986 INFO: Microblog startup [in /home/osboxes/PycharmProjects/Redo/Website-Ea-Group-Project/microblog/app/__init__.py:78]
2020-04-30 09:45:29,813 INFO: Microblog startup [in /home/osboxes/PycharmProjects/Redo/Website-Ea-Group-Project/microblog/app/__init__.py:78]
2020-04-30 09:45:33,976 INFO: Microblog startup [in /home/osboxes/PycharmProjects/Redo/Website-Ea-Group-Project/microblog/app/__init__.py:78]
2020-04-30 09:45:38,502 INFO: Microblog startup [in /home/osboxes/PycharmProjects/Redo/Website-Ea-Group-Project/microblog/app/__init__.py:78]
2020-04-30 09:45:42,317 INFO: Microblog startup [in /home/osboxes/PycharmProjects/Redo/Website-Ea-Group-Project/microblog/app/__init__.py:78]
2020-04-30 09:45:54,220 ERROR: Exception on /auth/login [POST] [in /home/osboxes/PycharmProjects/Redo/Website-Ea-Group-Project/microblog/venv/lib/python3.6/site-packages/flask/app.py:1761]
Traceback (most recent call last):
  File "/home/osboxes/PycharmProjects/Redo/Website-Ea-Group-Project/microblog/venv/lib/python3.6/site-packages/flask/app.py", line 2292, in wsgi_app
    response = self.full_dispatch_request()
  File "/home/osboxes/PycharmProjects/Redo/Website-Ea-Group-Project/microblog/venv/lib/python3.6/site-packages/flask/app.py", line 1815, in full_dispatch_request
    rv = self.handle_user_exception(e)
  File "/home/osboxes/PycharmProjects/Redo/Website-Ea-Group-Project/microblog/venv/lib/python3.6/site-packages/flask/app.py", line 1718, in handle_user_exception
    reraise(exc_type, exc_value, tb)
  File "/home/osboxes/PycharmProjects/Redo/Website-Ea-Group-Project/microblog/venv/lib/python3.6/site-packages/flask/_compat.py", line 35, in reraise
    raise value
  File "/home/osboxes/PycharmProjects/Redo/Website-Ea-Group-Project/microblog/venv/lib/python3.6/site-packages/flask/app.py", line 1813, in full_dispatch_request
    rv = self.dispatch_request()
  File "/home/osboxes/PycharmProjects/Redo/Website-Ea-Group-Project/microblog/venv/lib/python3.6/site-packages/flask/app.py", line 1799, in dispatch_request
    return self.view_functions[rule.endpoint](**req.view_args)
  File "/home/osboxes/PycharmProjects/Redo/Website-Ea-Group-Project/microblog/app/auth/routes.py", line 28, in login
    login_user(email, remember=form.remember_me.data)
  File "/home/osboxes/PycharmProjects/Redo/Website-Ea-Group-Project/microblog/venv/lib/python3.6/site-packages/flask_login/utils.py", line 158, in login_user
    if not force and not user.is_active:
AttributeError: 'User' object has no attribute 'is_active'
2020-04-30 09:47:14,918 ERROR: Exception on /auth/login [POST] [in /home/osboxes/PycharmProjects/Redo/Website-Ea-Group-Project/microblog/venv/lib/python3.6/site-packages/flask/app.py:1761]
Traceback (most recent call last):
  File "/home/osboxes/PycharmProjects/Redo/Website-Ea-Group-Project/microblog/venv/lib/python3.6/site-packages/flask/app.py", line 2292, in wsgi_app
    response = self.full_dispatch_request()
  File "/home/osboxes/PycharmProjects/Redo/Website-Ea-Group-Project/microblog/venv/lib/python3.6/site-packages/flask/app.py", line 1815, in full_dispatch_request
    rv = self.handle_user_exception(e)
  File "/home/osboxes/PycharmProjects/Redo/Website-Ea-Group-Project/microblog/venv/lib/python3.6/site-packages/flask/app.py", line 1718, in handle_user_exception
    reraise(exc_type, exc_value, tb)
  File "/home/osboxes/PycharmProjects/Redo/Website-Ea-Group-Project/microblog/venv/lib/python3.6/site-packages/flask/_compat.py", line 35, in reraise
    raise value
  File "/home/osboxes/PycharmProjects/Redo/Website-Ea-Group-Project/microblog/venv/lib/python3.6/site-packages/flask/app.py", line 1813, in full_dispatch_request
    rv = self.dispatch_request()
  File "/home/osboxes/PycharmProjects/Redo/Website-Ea-Group-Project/microblog/venv/lib/python3.6/site-packages/flask/app.py", line 1799, in dispatch_request
    return self.view_functions[rule.endpoint](**req.view_args)
  File "/home/osboxes/PycharmProjects/Redo/Website-Ea-Group-Project/microblog/app/auth/routes.py", line 28, in login
    login_user(email, remember=form.remember_me.data)
  File "/home/osboxes/PycharmProjects/Redo/Website-Ea-Group-Project/microblog/venv/lib/python3.6/site-packages/flask_login/utils.py", line 158, in login_user
    if not force and not user.is_active:
AttributeError: 'User' object has no attribute 'is_active'
2020-04-30 10:02:20,595 INFO: Microblog startup [in /home/osboxes/PycharmProjects/Redo/Website-Ea-Group-Project/microblog/app/__init__.py:78]
2020-04-30 10:03:44,807 INFO: Microblog startup [in /home/osboxes/PycharmProjects/Redo/Website-Ea-Group-Project/microblog/app/__init__.py:78]
2020-04-30 10:03:50,656 INFO: Microblog startup [in /home/osboxes/PycharmProjects/Redo/Website-Ea-Group-Project/microblog/app/__init__.py:78]
2020-04-30 10:03:57,827 INFO: Microblog startup [in /home/osboxes/PycharmProjects/Redo/Website-Ea-Group-Project/microblog/app/__init__.py:78]
2020-04-30 10:04:07,308 INFO: Microblog startup [in /home/osboxes/PycharmProjects/Redo/Website-Ea-Group-Project/microblog/app/__init__.py:78]
