2020-04-26 04:25:42,357 ERROR: Exception on /order_history/a [GET] [in /home/osboxes/PycharmProjects/Website-Ea-Group-Project/microblog/venv/lib/python3.6/site-packages/flask/app.py:1761]
Traceback (most recent call last):
  File "/home/osboxes/PycharmProjects/Website-Ea-Group-Project/microblog/venv/lib/python3.6/site-packages/flask/app.py", line 2292, in wsgi_app
    response = self.full_dispatch_request()
  File "/home/osboxes/PycharmProjects/Website-Ea-Group-Project/microblog/venv/lib/python3.6/site-packages/flask/app.py", line 1815, in full_dispatch_request
    rv = self.handle_user_exception(e)
  File "/home/osboxes/PycharmProjects/Website-Ea-Group-Project/microblog/venv/lib/python3.6/site-packages/flask/app.py", line 1718, in handle_user_exception
    reraise(exc_type, exc_value, tb)
  File "/home/osboxes/PycharmProjects/Website-Ea-Group-Project/microblog/venv/lib/python3.6/site-packages/flask/_compat.py", line 35, in reraise
    raise value
  File "/home/osboxes/PycharmProjects/Website-Ea-Group-Project/microblog/venv/lib/python3.6/site-packages/flask/app.py", line 1813, in full_dispatch_request
    rv = self.dispatch_request()
  File "/home/osboxes/PycharmProjects/Website-Ea-Group-Project/microblog/venv/lib/python3.6/site-packages/flask/app.py", line 1799, in dispatch_request
    return self.view_functions[rule.endpoint](**req.view_args)
  File "/home/osboxes/PycharmProjects/Website-Ea-Group-Project/microblog/venv/lib/python3.6/site-packages/flask_login/utils.py", line 261, in decorated_view
    return func(*args, **kwargs)
  File "/home/osboxes/PycharmProjects/Website-Ea-Group-Project/microblog/app/main/routes.py", line 261, in order_history
    order = Order.query.filter_by(user_id=current_user.id).all()
  File "/home/osboxes/PycharmProjects/Website-Ea-Group-Project/microblog/venv/lib/python3.6/site-packages/sqlalchemy/orm/query.py", line 2783, in all
    return list(self)
  File "/home/osboxes/PycharmProjects/Website-Ea-Group-Project/microblog/venv/lib/python3.6/site-packages/sqlalchemy/orm/loading.py", line 98, in instances
    util.raise_from_cause(err)
  File "/home/osboxes/PycharmProjects/Website-Ea-Group-Project/microblog/venv/lib/python3.6/site-packages/sqlalchemy/util/compat.py", line 203, in raise_from_cause
    reraise(type(exception), exception, tb=exc_tb, cause=cause)
  File "/home/osboxes/PycharmProjects/Website-Ea-Group-Project/microblog/venv/lib/python3.6/site-packages/sqlalchemy/util/compat.py", line 187, in reraise
    raise value
  File "/home/osboxes/PycharmProjects/Website-Ea-Group-Project/microblog/venv/lib/python3.6/site-packages/sqlalchemy/orm/loading.py", line 79, in instances
    rows = [proc(row) for row in fetch]
  File "/home/osboxes/PycharmProjects/Website-Ea-Group-Project/microblog/venv/lib/python3.6/site-packages/sqlalchemy/orm/loading.py", line 79, in <listcomp>
    rows = [proc(row) for row in fetch]
  File "/home/osboxes/PycharmProjects/Website-Ea-Group-Project/microblog/venv/lib/python3.6/site-packages/sqlalchemy/orm/loading.py", line 511, in _instance
    loaded_instance, populate_existing, populators)
  File "/home/osboxes/PycharmProjects/Website-Ea-Group-Project/microblog/venv/lib/python3.6/site-packages/sqlalchemy/orm/loading.py", line 611, in _populate_full
    dict_[key] = getter(row)
ValueError: Couldn't parse datetime string '1233' - value is not a string.
2020-04-26 04:26:42,462 ERROR: Exception on /order_history/a [GET] [in /home/osboxes/PycharmProjects/Website-Ea-Group-Project/microblog/venv/lib/python3.6/site-packages/flask/app.py:1761]
Traceback (most recent call last):
  File "/home/osboxes/PycharmProjects/Website-Ea-Group-Project/microblog/venv/lib/python3.6/site-packages/flask/app.py", line 2292, in wsgi_app
    response = self.full_dispatch_request()
  File "/home/osboxes/PycharmProjects/Website-Ea-Group-Project/microblog/venv/lib/python3.6/site-packages/flask/app.py", line 1815, in full_dispatch_request
    rv = self.handle_user_exception(e)
  File "/home/osboxes/PycharmProjects/Website-Ea-Group-Project/microblog/venv/lib/python3.6/site-packages/flask/app.py", line 1718, in handle_user_exception
    reraise(exc_type, exc_value, tb)
  File "/home/osboxes/PycharmProjects/Website-Ea-Group-Project/microblog/venv/lib/python3.6/site-packages/flask/_compat.py", line 35, in reraise
    raise value
  File "/home/osboxes/PycharmProjects/Website-Ea-Group-Project/microblog/venv/lib/python3.6/site-packages/flask/app.py", line 1813, in full_dispatch_request
    rv = self.dispatch_request()
  File "/home/osboxes/PycharmProjects/Website-Ea-Group-Project/microblog/venv/lib/python3.6/site-packages/flask/app.py", line 1799, in dispatch_request
    return self.view_functions[rule.endpoint](**req.view_args)
  File "/home/osboxes/PycharmProjects/Website-Ea-Group-Project/microblog/venv/lib/python3.6/site-packages/flask_login/utils.py", line 261, in decorated_view
    return func(*args, **kwargs)
  File "/home/osboxes/PycharmProjects/Website-Ea-Group-Project/microblog/app/main/routes.py", line 262, in order_history
    return render_template('order/order_history.html', title=_('order'), user=user, order=order)
  File "/home/osboxes/PycharmProjects/Website-Ea-Group-Project/microblog/venv/lib/python3.6/site-packages/flask/templating.py", line 135, in render_template
    context, ctx.app)
  File "/home/osboxes/PycharmProjects/Website-Ea-Group-Project/microblog/venv/lib/python3.6/site-packages/flask/templating.py", line 117, in _render
    rv = template.render(context)
  File "/home/osboxes/PycharmProjects/Website-Ea-Group-Project/microblog/venv/lib/python3.6/site-packages/jinja2/asyncsupport.py", line 76, in render
    return original_render(self, *args, **kwargs)
  File "/home/osboxes/PycharmProjects/Website-Ea-Group-Project/microblog/venv/lib/python3.6/site-packages/jinja2/environment.py", line 1008, in render
    return self.environment.handle_exception(exc_info, True)
  File "/home/osboxes/PycharmProjects/Website-Ea-Group-Project/microblog/venv/lib/python3.6/site-packages/jinja2/environment.py", line 780, in handle_exception
    reraise(exc_type, exc_value, tb)
  File "/home/osboxes/PycharmProjects/Website-Ea-Group-Project/microblog/venv/lib/python3.6/site-packages/jinja2/_compat.py", line 37, in reraise
    raise value.with_traceback(tb)
  File "/home/osboxes/PycharmProjects/Website-Ea-Group-Project/microblog/app/templates/order/order_history.html", line 5, in top-level template code
    {% import 'bootstrap/wtf.html' as wtf %}
  File "/home/osboxes/PycharmProjects/Website-Ea-Group-Project/microblog/app/templates/base.html", line 1, in top-level template code
    {% extends 'bootstrap/base.html' %}
  File "/home/osboxes/PycharmProjects/Website-Ea-Group-Project/microblog/venv/lib/python3.6/site-packages/flask_bootstrap/templates/bootstrap/base.html", line 1, in top-level template code
    {% block doc -%}
  File "/home/osboxes/PycharmProjects/Website-Ea-Group-Project/microblog/venv/lib/python3.6/site-packages/flask_bootstrap/templates/bootstrap/base.html", line 4, in block "doc"
    {%- block html %}
  File "/home/osboxes/PycharmProjects/Website-Ea-Group-Project/microblog/venv/lib/python3.6/site-packages/flask_bootstrap/templates/bootstrap/base.html", line 20, in block "html"
    {% block body -%}
  File "/home/osboxes/PycharmProjects/Website-Ea-Group-Project/microblog/venv/lib/python3.6/site-packages/flask_bootstrap/templates/bootstrap/base.html", line 23, in block "body"
    {% block content -%}
  File "/home/osboxes/PycharmProjects/Website-Ea-Group-Project/microblog/app/templates/base.html", line 201, in block "content"
    {% block current_app_content %}{% endblock %}
  File "/home/osboxes/PycharmProjects/Website-Ea-Group-Project/microblog/app/templates/order/order_history.html", line 42, in block "current_app_content"
    {% include 'message.html' %}
  File "/home/osboxes/PycharmProjects/Website-Ea-Group-Project/microblog/app/templates/message.html", line 5, in top-level template code
    {{ message.services }}
  File "/home/osboxes/PycharmProjects/Website-Ea-Group-Project/microblog/venv/lib/python3.6/site-packages/jinja2/environment.py", line 430, in getattr
    return getattr(obj, attribute)
jinja2.exceptions.UndefinedError: 'message' is undefined
2020-04-26 04:27:14,642 INFO: Microblog startup [in /home/osboxes/PycharmProjects/Website-Ea-Group-Project/microblog/app/__init__.py:78]
