2020-04-13 13:07:54,477 ERROR: Exception on /auth/register [POST] [in /home/osboxes/PycharmProjects/Website-Ea-Group-Project/microblog/venv/lib/python3.6/site-packages/flask/app.py:1761]
Traceback (most recent call last):
  File "/home/osboxes/PycharmProjects/Website-Ea-Group-Project/microblog/venv/lib/python3.6/site-packages/flask/app.py", line 2292, in wsgi_app
    response = self.full_dispatch_request()
  File "/home/osboxes/PycharmProjects/Website-Ea-Group-Project/microblog/venv/lib/python3.6/site-packages/flask/app.py", line 1815, in full_dispatch_request
    rv = self.handle_user_exception(e)
  File "/home/osboxes/PycharmProjects/Website-Ea-Group-Project/microblog/venv/lib/python3.6/site-packages/flask/app.py", line 1718, in handle_user_exception
    reraise(exc_type, exc_value, tb)
  File "/home/osboxes/PycharmProjects/Website-Ea-Group-Project/microblog/venv/lib/python3.6/site-packages/flask/_compat.py", line 35, in reraise
    raise value
  File "/home/osboxes/PycharmProjects/Website-Ea-Group-Project/microblog/venv/lib/python3.6/site-packages/flask/app.py", line 1813, in full_dispatch_request
    rv = self.dispatch_request()
  File "/home/osboxes/PycharmProjects/Website-Ea-Group-Project/microblog/venv/lib/python3.6/site-packages/flask/app.py", line 1799, in dispatch_request
    return self.view_functions[rule.endpoint](**req.view_args)
  File "/home/osboxes/PycharmProjects/Website-Ea-Group-Project/microblog/app/auth/routes.py", line 42, in register
    if form.validate_on_submit():
  File "/home/osboxes/PycharmProjects/Website-Ea-Group-Project/microblog/venv/lib/python3.6/site-packages/flask_wtf/form.py", line 101, in validate_on_submit
    return self.is_submitted() and self.validate()
  File "/home/osboxes/PycharmProjects/Website-Ea-Group-Project/microblog/venv/lib/python3.6/site-packages/wtforms/form.py", line 310, in validate
    return super(Form, self).validate(extra)
  File "/home/osboxes/PycharmProjects/Website-Ea-Group-Project/microblog/venv/lib/python3.6/site-packages/wtforms/form.py", line 152, in validate
    if not field.validate(self, extra):
  File "/home/osboxes/PycharmProjects/Website-Ea-Group-Project/microblog/venv/lib/python3.6/site-packages/wtforms/fields/core.py", line 206, in validate
    stop_validation = self._run_validation_chain(form, chain)
  File "/home/osboxes/PycharmProjects/Website-Ea-Group-Project/microblog/venv/lib/python3.6/site-packages/wtforms/fields/core.py", line 226, in _run_validation_chain
    validator(form, self)
  File "/home/osboxes/PycharmProjects/Website-Ea-Group-Project/microblog/app/auth/forms.py", line 42, in validate_phone
    if user > 9:
TypeError: '>' not supported between instances of 'NoneType' and 'int'
2020-04-13 13:34:54,164 INFO: Microblog startup [in /home/osboxes/PycharmProjects/Website-Ea-Group-Project/microblog/app/__init__.py:75]
2020-04-13 13:41:03,289 INFO: Microblog startup [in /home/osboxes/PycharmProjects/Website-Ea-Group-Project/microblog/app/__init__.py:75]
2020-04-13 13:45:17,599 INFO: Microblog startup [in /home/osboxes/PycharmProjects/Website-Ea-Group-Project/microblog/app/__init__.py:75]
2020-04-14 09:45:58,630 INFO: Microblog startup [in /home/osboxes/PycharmProjects/Website-Ea-Group-Project/microblog/app/__init__.py:75]
2020-04-14 10:04:59,550 INFO: Microblog startup [in /home/osboxes/PycharmProjects/Website-Ea-Group-Project/microblog/app/__init__.py:75]
2020-04-14 10:38:28,962 INFO: Microblog startup [in /home/osboxes/PycharmProjects/Website-Ea-Group-Project/microblog/app/__init__.py:75]
2020-04-14 10:38:47,018 INFO: Microblog startup [in /home/osboxes/PycharmProjects/Website-Ea-Group-Project/microblog/app/__init__.py:75]
