2020-04-25 08:39:39,309 ERROR: Exception on / [GET] [in /home/osboxes/PycharmProjects/Redo/Website-Ea-Group-Project/microblog/venv/lib/python3.6/site-packages/flask/app.py:1761]
Traceback (most recent call last):
  File "/home/osboxes/PycharmProjects/Redo/Website-Ea-Group-Project/microblog/venv/lib/python3.6/site-packages/flask/app.py", line 2292, in wsgi_app
    response = self.full_dispatch_request()
  File "/home/osboxes/PycharmProjects/Redo/Website-Ea-Group-Project/microblog/venv/lib/python3.6/site-packages/flask/app.py", line 1815, in full_dispatch_request
    rv = self.handle_user_exception(e)
  File "/home/osboxes/PycharmProjects/Redo/Website-Ea-Group-Project/microblog/venv/lib/python3.6/site-packages/flask/app.py", line 1718, in handle_user_exception
    reraise(exc_type, exc_value, tb)
  File "/home/osboxes/PycharmProjects/Redo/Website-Ea-Group-Project/microblog/venv/lib/python3.6/site-packages/flask/_compat.py", line 35, in reraise
    raise value
  File "/home/osboxes/PycharmProjects/Redo/Website-Ea-Group-Project/microblog/venv/lib/python3.6/site-packages/flask/app.py", line 1813, in full_dispatch_request
    rv = self.dispatch_request()
  File "/home/osboxes/PycharmProjects/Redo/Website-Ea-Group-Project/microblog/venv/lib/python3.6/site-packages/flask/app.py", line 1799, in dispatch_request
    return self.view_functions[rule.endpoint](**req.view_args)
  File "/home/osboxes/PycharmProjects/Redo/Website-Ea-Group-Project/microblog/app/main/routes.py", line 28, in index
    return render_template('index.html', title=_('Home'), prod=prod)
  File "/home/osboxes/PycharmProjects/Redo/Website-Ea-Group-Project/microblog/venv/lib/python3.6/site-packages/flask/templating.py", line 135, in render_template
    context, ctx.app)
  File "/home/osboxes/PycharmProjects/Redo/Website-Ea-Group-Project/microblog/venv/lib/python3.6/site-packages/flask/templating.py", line 117, in _render
    rv = template.render(context)
  File "/home/osboxes/PycharmProjects/Redo/Website-Ea-Group-Project/microblog/venv/lib/python3.6/site-packages/jinja2/asyncsupport.py", line 76, in render
    return original_render(self, *args, **kwargs)
  File "/home/osboxes/PycharmProjects/Redo/Website-Ea-Group-Project/microblog/venv/lib/python3.6/site-packages/jinja2/environment.py", line 1008, in render
    return self.environment.handle_exception(exc_info, True)
  File "/home/osboxes/PycharmProjects/Redo/Website-Ea-Group-Project/microblog/venv/lib/python3.6/site-packages/jinja2/environment.py", line 780, in handle_exception
    reraise(exc_type, exc_value, tb)
  File "/home/osboxes/PycharmProjects/Redo/Website-Ea-Group-Project/microblog/venv/lib/python3.6/site-packages/jinja2/_compat.py", line 37, in reraise
    raise value.with_traceback(tb)
  File "/home/osboxes/PycharmProjects/Redo/Website-Ea-Group-Project/microblog/app/templates/index.html", line 2, in top-level template code
    {% import 'bootstrap/wtf.html' as wtf %}
  File "/home/osboxes/PycharmProjects/Redo/Website-Ea-Group-Project/microblog/app/templates/base.html", line 1, in top-level template code
    {% extends 'bootstrap/base.html' %}
  File "/home/osboxes/PycharmProjects/Redo/Website-Ea-Group-Project/microblog/venv/lib/python3.6/site-packages/flask_bootstrap/templates/bootstrap/base.html", line 1, in top-level template code
    {% block doc -%}
  File "/home/osboxes/PycharmProjects/Redo/Website-Ea-Group-Project/microblog/venv/lib/python3.6/site-packages/flask_bootstrap/templates/bootstrap/base.html", line 4, in block "doc"
    {%- block html %}
  File "/home/osboxes/PycharmProjects/Redo/Website-Ea-Group-Project/microblog/venv/lib/python3.6/site-packages/flask_bootstrap/templates/bootstrap/base.html", line 20, in block "html"
    {% block body -%}
  File "/home/osboxes/PycharmProjects/Redo/Website-Ea-Group-Project/microblog/venv/lib/python3.6/site-packages/flask_bootstrap/templates/bootstrap/base.html", line 23, in block "body"
    {% block content -%}
  File "/home/osboxes/PycharmProjects/Redo/Website-Ea-Group-Project/microblog/app/templates/base.html", line 201, in block "content"
    {% block current_app_content %}{% endblock %}
  File "/home/osboxes/PycharmProjects/Redo/Website-Ea-Group-Project/microblog/app/templates/index.html", line 164, in block "current_app_content"
    <a class="btn btn-success" href="{{ url_for('main./add_to_cart', prod_id=product.pid ) }}" role="button">Add to Cart</a>
  File "/home/osboxes/PycharmProjects/Redo/Website-Ea-Group-Project/microblog/venv/lib/python3.6/site-packages/flask/helpers.py", line 356, in url_for
    return appctx.app.handle_url_build_error(error, endpoint, values)
  File "/home/osboxes/PycharmProjects/Redo/Website-Ea-Group-Project/microblog/venv/lib/python3.6/site-packages/flask/app.py", line 2061, in handle_url_build_error
    reraise(exc_type, exc_value, tb)
  File "/home/osboxes/PycharmProjects/Redo/Website-Ea-Group-Project/microblog/venv/lib/python3.6/site-packages/flask/_compat.py", line 35, in reraise
    raise value
  File "/home/osboxes/PycharmProjects/Redo/Website-Ea-Group-Project/microblog/venv/lib/python3.6/site-packages/flask/helpers.py", line 345, in url_for
    force_external=external)
  File "/home/osboxes/PycharmProjects/Redo/Website-Ea-Group-Project/microblog/venv/lib/python3.6/site-packages/werkzeug/routing.py", line 1776, in build
    raise BuildError(endpoint, values, method, self)
werkzeug.routing.BuildError: Could not build url for endpoint 'main./add_to_cart' with values ['prod_id']. Did you mean 'main.add_to_cart' instead?
2020-04-25 08:39:49,238 INFO: Microblog startup [in /home/osboxes/PycharmProjects/Redo/Website-Ea-Group-Project/microblog/app/__init__.py:78]
2020-04-25 08:39:54,525 ERROR: Exception on /add_to_cart/990 [GET] [in /home/osboxes/PycharmProjects/Redo/Website-Ea-Group-Project/microblog/venv/lib/python3.6/site-packages/flask/app.py:1761]
Traceback (most recent call last):
  File "/home/osboxes/PycharmProjects/Redo/Website-Ea-Group-Project/microblog/venv/lib/python3.6/site-packages/flask/app.py", line 2292, in wsgi_app
    response = self.full_dispatch_request()
  File "/home/osboxes/PycharmProjects/Redo/Website-Ea-Group-Project/microblog/venv/lib/python3.6/site-packages/flask/app.py", line 1815, in full_dispatch_request
    rv = self.handle_user_exception(e)
  File "/home/osboxes/PycharmProjects/Redo/Website-Ea-Group-Project/microblog/venv/lib/python3.6/site-packages/flask/app.py", line 1718, in handle_user_exception
    reraise(exc_type, exc_value, tb)
  File "/home/osboxes/PycharmProjects/Redo/Website-Ea-Group-Project/microblog/venv/lib/python3.6/site-packages/flask/_compat.py", line 35, in reraise
    raise value
  File "/home/osboxes/PycharmProjects/Redo/Website-Ea-Group-Project/microblog/venv/lib/python3.6/site-packages/flask/app.py", line 1813, in full_dispatch_request
    rv = self.dispatch_request()
  File "/home/osboxes/PycharmProjects/Redo/Website-Ea-Group-Project/microblog/venv/lib/python3.6/site-packages/flask/app.py", line 1799, in dispatch_request
    return self.view_functions[rule.endpoint](**req.view_args)
  File "/home/osboxes/PycharmProjects/Redo/Website-Ea-Group-Project/microblog/app/main/routes.py", line 33, in add_to_cart
    cart_item = Shopping_cart(user_id=current_user.id, product_id=prod_id, qty=1,
  File "/home/osboxes/PycharmProjects/Redo/Website-Ea-Group-Project/microblog/venv/lib/python3.6/site-packages/werkzeug/local.py", line 347, in __getattr__
    return getattr(self._get_current_object(), name)
AttributeError: 'AnonymousUserMixin' object has no attribute 'id'
2020-04-25 08:44:58,842 INFO: Microblog startup [in /home/osboxes/PycharmProjects/Redo/Website-Ea-Group-Project/microblog/app/__init__.py:78]
2020-04-25 08:45:07,043 ERROR: Exception on /add_to_cart/991 [GET] [in /home/osboxes/PycharmProjects/Redo/Website-Ea-Group-Project/microblog/venv/lib/python3.6/site-packages/flask/app.py:1761]
Traceback (most recent call last):
  File "/home/osboxes/PycharmProjects/Redo/Website-Ea-Group-Project/microblog/venv/lib/python3.6/site-packages/flask/app.py", line 2292, in wsgi_app
    response = self.full_dispatch_request()
  File "/home/osboxes/PycharmProjects/Redo/Website-Ea-Group-Project/microblog/venv/lib/python3.6/site-packages/flask/app.py", line 1815, in full_dispatch_request
    rv = self.handle_user_exception(e)
  File "/home/osboxes/PycharmProjects/Redo/Website-Ea-Group-Project/microblog/venv/lib/python3.6/site-packages/flask/app.py", line 1718, in handle_user_exception
    reraise(exc_type, exc_value, tb)
  File "/home/osboxes/PycharmProjects/Redo/Website-Ea-Group-Project/microblog/venv/lib/python3.6/site-packages/flask/_compat.py", line 35, in reraise
    raise value
  File "/home/osboxes/PycharmProjects/Redo/Website-Ea-Group-Project/microblog/venv/lib/python3.6/site-packages/flask/app.py", line 1813, in full_dispatch_request
    rv = self.dispatch_request()
  File "/home/osboxes/PycharmProjects/Redo/Website-Ea-Group-Project/microblog/venv/lib/python3.6/site-packages/flask/app.py", line 1799, in dispatch_request
    return self.view_functions[rule.endpoint](**req.view_args)
  File "/home/osboxes/PycharmProjects/Redo/Website-Ea-Group-Project/microblog/app/main/routes.py", line 42, in add_to_cart
    db.Session.add(cart_item)
TypeError: add() missing 1 required positional argument: 'instance'
2020-04-25 08:51:38,211 INFO: Microblog startup [in /home/osboxes/PycharmProjects/Redo/Website-Ea-Group-Project/microblog/app/__init__.py:78]
