2020-04-30 08:57:27,557 ERROR: Exception on /init [GET] [in /home/osboxes/PycharmProjects/Redo/Website-Ea-Group-Project/microblog/venv/lib/python3.6/site-packages/flask/app.py:1761]
Traceback (most recent call last):
  File "/home/osboxes/PycharmProjects/Redo/Website-Ea-Group-Project/microblog/venv/lib/python3.6/site-packages/sqlalchemy/engine/base.py", line 1127, in _execute_context
    context = constructor(dialect, self, conn, *args)
  File "/home/osboxes/PycharmProjects/Redo/Website-Ea-Group-Project/microblog/venv/lib/python3.6/site-packages/sqlalchemy/engine/default.py", line 668, in _init_compiled
    param.append(processors[key](compiled_params[key]))
  File "/home/osboxes/PycharmProjects/Redo/Website-Ea-Group-Project/microblog/venv/lib/python3.6/site-packages/sqlalchemy/dialects/sqlite/base.py", line 610, in process
    raise TypeError("SQLite DateTime type only accepts Python "
TypeError: SQLite DateTime type only accepts Python datetime and date objects as input.

The above exception was the direct cause of the following exception:

Traceback (most recent call last):
  File "/home/osboxes/PycharmProjects/Redo/Website-Ea-Group-Project/microblog/venv/lib/python3.6/site-packages/flask/app.py", line 2292, in wsgi_app
    response = self.full_dispatch_request()
  File "/home/osboxes/PycharmProjects/Redo/Website-Ea-Group-Project/microblog/venv/lib/python3.6/site-packages/flask/app.py", line 1815, in full_dispatch_request
    rv = self.handle_user_exception(e)
  File "/home/osboxes/PycharmProjects/Redo/Website-Ea-Group-Project/microblog/venv/lib/python3.6/site-packages/flask/app.py", line 1718, in handle_user_exception
    reraise(exc_type, exc_value, tb)
  File "/home/osboxes/PycharmProjects/Redo/Website-Ea-Group-Project/microblog/venv/lib/python3.6/site-packages/flask/_compat.py", line 35, in reraise
    raise value
  File "/home/osboxes/PycharmProjects/Redo/Website-Ea-Group-Project/microblog/venv/lib/python3.6/site-packages/flask/app.py", line 1813, in full_dispatch_request
    rv = self.dispatch_request()
  File "/home/osboxes/PycharmProjects/Redo/Website-Ea-Group-Project/microblog/venv/lib/python3.6/site-packages/flask/app.py", line 1799, in dispatch_request
    return self.view_functions[rule.endpoint](**req.view_args)
  File "/home/osboxes/PycharmProjects/Redo/Website-Ea-Group-Project/microblog/app/main/routes.py", line 498, in init
    db.session.commit()
  File "/home/osboxes/PycharmProjects/Redo/Website-Ea-Group-Project/microblog/venv/lib/python3.6/site-packages/sqlalchemy/orm/scoping.py", line 153, in do
    return getattr(self.registry(), name)(*args, **kwargs)
  File "/home/osboxes/PycharmProjects/Redo/Website-Ea-Group-Project/microblog/venv/lib/python3.6/site-packages/sqlalchemy/orm/session.py", line 943, in commit
    self.transaction.commit()
  File "/home/osboxes/PycharmProjects/Redo/Website-Ea-Group-Project/microblog/venv/lib/python3.6/site-packages/sqlalchemy/orm/session.py", line 467, in commit
    self._prepare_impl()
  File "/home/osboxes/PycharmProjects/Redo/Website-Ea-Group-Project/microblog/venv/lib/python3.6/site-packages/sqlalchemy/orm/session.py", line 447, in _prepare_impl
    self.session.flush()
  File "/home/osboxes/PycharmProjects/Redo/Website-Ea-Group-Project/microblog/venv/lib/python3.6/site-packages/sqlalchemy/orm/session.py", line 2254, in flush
    self._flush(objects)
  File "/home/osboxes/PycharmProjects/Redo/Website-Ea-Group-Project/microblog/venv/lib/python3.6/site-packages/sqlalchemy/orm/session.py", line 2380, in _flush
    transaction.rollback(_capture_exception=True)
  File "/home/osboxes/PycharmProjects/Redo/Website-Ea-Group-Project/microblog/venv/lib/python3.6/site-packages/sqlalchemy/util/langhelpers.py", line 66, in __exit__
    compat.reraise(exc_type, exc_value, exc_tb)
  File "/home/osboxes/PycharmProjects/Redo/Website-Ea-Group-Project/microblog/venv/lib/python3.6/site-packages/sqlalchemy/util/compat.py", line 187, in reraise
    raise value
  File "/home/osboxes/PycharmProjects/Redo/Website-Ea-Group-Project/microblog/venv/lib/python3.6/site-packages/sqlalchemy/orm/session.py", line 2344, in _flush
    flush_context.execute()
  File "/home/osboxes/PycharmProjects/Redo/Website-Ea-Group-Project/microblog/venv/lib/python3.6/site-packages/sqlalchemy/orm/unitofwork.py", line 391, in execute
    rec.execute(self)
  File "/home/osboxes/PycharmProjects/Redo/Website-Ea-Group-Project/microblog/venv/lib/python3.6/site-packages/sqlalchemy/orm/unitofwork.py", line 556, in execute
    uow
  File "/home/osboxes/PycharmProjects/Redo/Website-Ea-Group-Project/microblog/venv/lib/python3.6/site-packages/sqlalchemy/orm/persistence.py", line 181, in save_obj
    mapper, table, insert)
  File "/home/osboxes/PycharmProjects/Redo/Website-Ea-Group-Project/microblog/venv/lib/python3.6/site-packages/sqlalchemy/orm/persistence.py", line 830, in _emit_insert_statements
    execute(statement, multiparams)
  File "/home/osboxes/PycharmProjects/Redo/Website-Ea-Group-Project/microblog/venv/lib/python3.6/site-packages/sqlalchemy/engine/base.py", line 948, in execute
    return meth(self, multiparams, params)
  File "/home/osboxes/PycharmProjects/Redo/Website-Ea-Group-Project/microblog/venv/lib/python3.6/site-packages/sqlalchemy/sql/elements.py", line 269, in _execute_on_connection
    return connection._execute_clauseelement(self, multiparams, params)
  File "/home/osboxes/PycharmProjects/Redo/Website-Ea-Group-Project/microblog/venv/lib/python3.6/site-packages/sqlalchemy/engine/base.py", line 1060, in _execute_clauseelement
    compiled_sql, distilled_params
  File "/home/osboxes/PycharmProjects/Redo/Website-Ea-Group-Project/microblog/venv/lib/python3.6/site-packages/sqlalchemy/engine/base.py", line 1132, in _execute_context
    None, None)
  File "/home/osboxes/PycharmProjects/Redo/Website-Ea-Group-Project/microblog/venv/lib/python3.6/site-packages/sqlalchemy/engine/base.py", line 1413, in _handle_dbapi_exception
    exc_info
  File "/home/osboxes/PycharmProjects/Redo/Website-Ea-Group-Project/microblog/venv/lib/python3.6/site-packages/sqlalchemy/util/compat.py", line 203, in raise_from_cause
    reraise(type(exception), exception, tb=exc_tb, cause=cause)
  File "/home/osboxes/PycharmProjects/Redo/Website-Ea-Group-Project/microblog/venv/lib/python3.6/site-packages/sqlalchemy/util/compat.py", line 186, in reraise
    raise value.with_traceback(tb)
  File "/home/osboxes/PycharmProjects/Redo/Website-Ea-Group-Project/microblog/venv/lib/python3.6/site-packages/sqlalchemy/engine/base.py", line 1127, in _execute_context
    context = constructor(dialect, self, conn, *args)
  File "/home/osboxes/PycharmProjects/Redo/Website-Ea-Group-Project/microblog/venv/lib/python3.6/site-packages/sqlalchemy/engine/default.py", line 668, in _init_compiled
    param.append(processors[key](compiled_params[key]))
  File "/home/osboxes/PycharmProjects/Redo/Website-Ea-Group-Project/microblog/venv/lib/python3.6/site-packages/sqlalchemy/dialects/sqlite/base.py", line 610, in process
    raise TypeError("SQLite DateTime type only accepts Python "
sqlalchemy.exc.StatementError: (builtins.TypeError) SQLite DateTime type only accepts Python datetime and date objects as input. [SQL: 'INSERT INTO user (id, first_name, last_name, username, email, phone, password_hash, gender, last_seen) VALUES (?, ?, ?, ?, ?, ?, ?, ?, ?)'] [parameters: [{'last_seen': '2020-04-28 02:23:23.805988', 'phone': 132, 'first_name': 'a', 'email': 'a@g.com', 'id': 0, 'password_hash': 'pbkdf2:sha256:50000$K1aBNTtq$a627489faa2332223c5225bbc26a9c875d57437fa4865b83875eeb957b3f04dd', 'username': 'a', 'last_name': 'a', 'gender': None}]]
2020-04-30 08:58:42,831 INFO: Microblog startup [in /home/osboxes/PycharmProjects/Redo/Website-Ea-Group-Project/microblog/app/__init__.py:78]
