2020-04-28 10:40:24,237 ERROR: Exception on /post [GET] [in /home/osboxes/PycharmProjects/Website-Ea-Group-Project/microblog/venv/lib/python3.6/site-packages/flask/app.py:1761]
Traceback (most recent call last):
  File "/home/osboxes/PycharmProjects/Website-Ea-Group-Project/microblog/venv/lib/python3.6/site-packages/flask/app.py", line 2292, in wsgi_app
    response = self.full_dispatch_request()
  File "/home/osboxes/PycharmProjects/Website-Ea-Group-Project/microblog/venv/lib/python3.6/site-packages/flask/app.py", line 1815, in full_dispatch_request
    rv = self.handle_user_exception(e)
  File "/home/osboxes/PycharmProjects/Website-Ea-Group-Project/microblog/venv/lib/python3.6/site-packages/flask/app.py", line 1718, in handle_user_exception
    reraise(exc_type, exc_value, tb)
  File "/home/osboxes/PycharmProjects/Website-Ea-Group-Project/microblog/venv/lib/python3.6/site-packages/flask/_compat.py", line 35, in reraise
    raise value
  File "/home/osboxes/PycharmProjects/Website-Ea-Group-Project/microblog/venv/lib/python3.6/site-packages/flask/app.py", line 1813, in full_dispatch_request
    rv = self.dispatch_request()
  File "/home/osboxes/PycharmProjects/Website-Ea-Group-Project/microblog/venv/lib/python3.6/site-packages/flask/app.py", line 1799, in dispatch_request
    return self.view_functions[rule.endpoint](**req.view_args)
  File "/home/osboxes/PycharmProjects/Website-Ea-Group-Project/microblog/venv/lib/python3.6/site-packages/flask_login/utils.py", line 261, in decorated_view
    return func(*args, **kwargs)
  File "/home/osboxes/PycharmProjects/Website-Ea-Group-Project/microblog/app/main/routes.py", line 62, in post
    posts = current_user.followed_posts().paginate(
  File "/home/osboxes/PycharmProjects/Website-Ea-Group-Project/microblog/venv/lib/python3.6/site-packages/werkzeug/local.py", line 347, in __getattr__
    return getattr(self._get_current_object(), name)
AttributeError: 'User' object has no attribute 'followed_posts'
2020-04-28 10:41:02,946 INFO: Microblog startup [in /home/osboxes/PycharmProjects/Website-Ea-Group-Project/microblog/app/__init__.py:78]
2020-04-28 10:43:34,111 INFO: Microblog startup [in /home/osboxes/PycharmProjects/Website-Ea-Group-Project/microblog/app/__init__.py:78]
2020-04-28 10:44:46,048 INFO: Microblog startup [in /home/osboxes/PycharmProjects/Website-Ea-Group-Project/microblog/app/__init__.py:78]
2020-04-28 10:45:53,481 INFO: Microblog startup [in /home/osboxes/PycharmProjects/Website-Ea-Group-Project/microblog/app/__init__.py:78]
2020-04-28 10:48:19,677 INFO: Microblog startup [in /home/osboxes/PycharmProjects/Website-Ea-Group-Project/microblog/app/__init__.py:78]
2020-04-28 10:49:10,657 INFO: Microblog startup [in /home/osboxes/PycharmProjects/Website-Ea-Group-Project/microblog/app/__init__.py:78]
2020-04-28 10:49:14,498 ERROR: Exception on /housewares [GET] [in /home/osboxes/PycharmProjects/Website-Ea-Group-Project/microblog/venv/lib/python3.6/site-packages/flask/app.py:1761]
Traceback (most recent call last):
  File "/home/osboxes/PycharmProjects/Website-Ea-Group-Project/microblog/venv/lib/python3.6/site-packages/flask/app.py", line 2292, in wsgi_app
    response = self.full_dispatch_request()
  File "/home/osboxes/PycharmProjects/Website-Ea-Group-Project/microblog/venv/lib/python3.6/site-packages/flask/app.py", line 1815, in full_dispatch_request
    rv = self.handle_user_exception(e)
  File "/home/osboxes/PycharmProjects/Website-Ea-Group-Project/microblog/venv/lib/python3.6/site-packages/flask/app.py", line 1718, in handle_user_exception
    reraise(exc_type, exc_value, tb)
  File "/home/osboxes/PycharmProjects/Website-Ea-Group-Project/microblog/venv/lib/python3.6/site-packages/flask/_compat.py", line 35, in reraise
    raise value
  File "/home/osboxes/PycharmProjects/Website-Ea-Group-Project/microblog/venv/lib/python3.6/site-packages/flask/app.py", line 1813, in full_dispatch_request
    rv = self.dispatch_request()
  File "/home/osboxes/PycharmProjects/Website-Ea-Group-Project/microblog/venv/lib/python3.6/site-packages/flask/app.py", line 1799, in dispatch_request
    return self.view_functions[rule.endpoint](**req.view_args)
  File "/home/osboxes/PycharmProjects/Website-Ea-Group-Project/microblog/app/main/routes.py", line 120, in housewares
    return render_template('housewares.html', title=_('Home'), products=products)
  File "/home/osboxes/PycharmProjects/Website-Ea-Group-Project/microblog/venv/lib/python3.6/site-packages/flask/templating.py", line 135, in render_template
    context, ctx.app)
  File "/home/osboxes/PycharmProjects/Website-Ea-Group-Project/microblog/venv/lib/python3.6/site-packages/flask/templating.py", line 117, in _render
    rv = template.render(context)
  File "/home/osboxes/PycharmProjects/Website-Ea-Group-Project/microblog/venv/lib/python3.6/site-packages/jinja2/asyncsupport.py", line 76, in render
    return original_render(self, *args, **kwargs)
  File "/home/osboxes/PycharmProjects/Website-Ea-Group-Project/microblog/venv/lib/python3.6/site-packages/jinja2/environment.py", line 1008, in render
    return self.environment.handle_exception(exc_info, True)
  File "/home/osboxes/PycharmProjects/Website-Ea-Group-Project/microblog/venv/lib/python3.6/site-packages/jinja2/environment.py", line 780, in handle_exception
    reraise(exc_type, exc_value, tb)
  File "/home/osboxes/PycharmProjects/Website-Ea-Group-Project/microblog/venv/lib/python3.6/site-packages/jinja2/_compat.py", line 37, in reraise
    raise value.with_traceback(tb)
  File "/home/osboxes/PycharmProjects/Website-Ea-Group-Project/microblog/app/templates/housewares.html", line 2, in top-level template code
    {% import 'bootstrap/wtf.html' as wtf %}
  File "/home/osboxes/PycharmProjects/Website-Ea-Group-Project/microblog/app/templates/base.html", line 1, in top-level template code
    {% extends 'bootstrap/base.html' %}
  File "/home/osboxes/PycharmProjects/Website-Ea-Group-Project/microblog/venv/lib/python3.6/site-packages/flask_bootstrap/templates/bootstrap/base.html", line 1, in top-level template code
    {% block doc -%}
  File "/home/osboxes/PycharmProjects/Website-Ea-Group-Project/microblog/venv/lib/python3.6/site-packages/flask_bootstrap/templates/bootstrap/base.html", line 4, in block "doc"
    {%- block html %}
  File "/home/osboxes/PycharmProjects/Website-Ea-Group-Project/microblog/venv/lib/python3.6/site-packages/flask_bootstrap/templates/bootstrap/base.html", line 20, in block "html"
    {% block body -%}
  File "/home/osboxes/PycharmProjects/Website-Ea-Group-Project/microblog/venv/lib/python3.6/site-packages/flask_bootstrap/templates/bootstrap/base.html", line 23, in block "body"
    {% block content -%}
  File "/home/osboxes/PycharmProjects/Website-Ea-Group-Project/microblog/app/templates/base.html", line 219, in block "content"
    {% block current_app_content %}{% endblock %}
  File "/home/osboxes/PycharmProjects/Website-Ea-Group-Project/microblog/app/templates/housewares.html", line 164, in block "current_app_content"
    <a class="btn btn-success" href="{{ url_for('main.add_to_cart', prod_id=housewares.pid ) }}" role="button">Add to Cart</a>
  File "/home/osboxes/PycharmProjects/Website-Ea-Group-Project/microblog/venv/lib/python3.6/site-packages/flask/helpers.py", line 345, in url_for
    force_external=external)
  File "/home/osboxes/PycharmProjects/Website-Ea-Group-Project/microblog/venv/lib/python3.6/site-packages/werkzeug/routing.py", line 1774, in build
    rv = self._partial_build(endpoint, values, method, append_unknown)
  File "/home/osboxes/PycharmProjects/Website-Ea-Group-Project/microblog/venv/lib/python3.6/site-packages/werkzeug/routing.py", line 1689, in _partial_build
    append_unknown)
  File "/home/osboxes/PycharmProjects/Website-Ea-Group-Project/microblog/venv/lib/python3.6/site-packages/werkzeug/routing.py", line 1697, in _partial_build
    rv = rule.build(values, append_unknown)
  File "/home/osboxes/PycharmProjects/Website-Ea-Group-Project/microblog/venv/lib/python3.6/site-packages/werkzeug/routing.py", line 809, in build
    add(self._converters[data].to_url(values[data]))
  File "/home/osboxes/PycharmProjects/Website-Ea-Group-Project/microblog/venv/lib/python3.6/site-packages/werkzeug/routing.py", line 1034, in to_url
    value = self.num_convert(value)
jinja2.exceptions.UndefinedError: 'sqlalchemy.util._collections.result object' has no attribute 'pid'
2020-04-28 10:49:29,528 INFO: Microblog startup [in /home/osboxes/PycharmProjects/Website-Ea-Group-Project/microblog/app/__init__.py:78]
