2020-04-29 11:44:35,118 ERROR: Exception on / [GET] [in /home/osboxes/PycharmProjects/Website-Ea-Group-Project/microblog/venv/lib/python3.6/site-packages/flask/app.py:1761]
Traceback (most recent call last):
  File "/home/osboxes/PycharmProjects/Website-Ea-Group-Project/microblog/venv/lib/python3.6/site-packages/sqlalchemy/engine/base.py", line 1193, in _execute_context
    context)
  File "/home/osboxes/PycharmProjects/Website-Ea-Group-Project/microblog/venv/lib/python3.6/site-packages/sqlalchemy/engine/default.py", line 508, in do_execute
    cursor.execute(statement, parameters)
  File "/home/osboxes/PycharmProjects/Website-Ea-Group-Project/microblog/venv/lib/python3.6/site-packages/pymysql/cursors.py", line 170, in execute
    result = self._query(query)
  File "/home/osboxes/PycharmProjects/Website-Ea-Group-Project/microblog/venv/lib/python3.6/site-packages/pymysql/cursors.py", line 328, in _query
    conn.query(q)
  File "/home/osboxes/PycharmProjects/Website-Ea-Group-Project/microblog/venv/lib/python3.6/site-packages/pymysql/connections.py", line 516, in query
    self._affected_rows = self._read_query_result(unbuffered=unbuffered)
  File "/home/osboxes/PycharmProjects/Website-Ea-Group-Project/microblog/venv/lib/python3.6/site-packages/pymysql/connections.py", line 727, in _read_query_result
    result.read()
  File "/home/osboxes/PycharmProjects/Website-Ea-Group-Project/microblog/venv/lib/python3.6/site-packages/pymysql/connections.py", line 1066, in read
    first_packet = self.connection._read_packet()
  File "/home/osboxes/PycharmProjects/Website-Ea-Group-Project/microblog/venv/lib/python3.6/site-packages/pymysql/connections.py", line 683, in _read_packet
    packet.check_error()
  File "/home/osboxes/PycharmProjects/Website-Ea-Group-Project/microblog/venv/lib/python3.6/site-packages/pymysql/protocol.py", line 220, in check_error
    err.raise_mysql_exception(self._data)
  File "/home/osboxes/PycharmProjects/Website-Ea-Group-Project/microblog/venv/lib/python3.6/site-packages/pymysql/err.py", line 109, in raise_mysql_exception
    raise errorclass(errno, errval)
pymysql.err.ProgrammingError: (1146, "Table 'app.user' doesn't exist")

The above exception was the direct cause of the following exception:

Traceback (most recent call last):
  File "/home/osboxes/PycharmProjects/Website-Ea-Group-Project/microblog/venv/lib/python3.6/site-packages/flask/app.py", line 2292, in wsgi_app
    response = self.full_dispatch_request()
  File "/home/osboxes/PycharmProjects/Website-Ea-Group-Project/microblog/venv/lib/python3.6/site-packages/flask/app.py", line 1815, in full_dispatch_request
    rv = self.handle_user_exception(e)
  File "/home/osboxes/PycharmProjects/Website-Ea-Group-Project/microblog/venv/lib/python3.6/site-packages/flask/app.py", line 1718, in handle_user_exception
    reraise(exc_type, exc_value, tb)
  File "/home/osboxes/PycharmProjects/Website-Ea-Group-Project/microblog/venv/lib/python3.6/site-packages/flask/_compat.py", line 35, in reraise
    raise value
  File "/home/osboxes/PycharmProjects/Website-Ea-Group-Project/microblog/venv/lib/python3.6/site-packages/flask/app.py", line 1811, in full_dispatch_request
    rv = self.preprocess_request()
  File "/home/osboxes/PycharmProjects/Website-Ea-Group-Project/microblog/venv/lib/python3.6/site-packages/flask/app.py", line 2087, in preprocess_request
    rv = func()
  File "/home/osboxes/PycharmProjects/Website-Ea-Group-Project/microblog/app/main/routes.py", line 16, in before_request
    if current_user.is_authenticated:
  File "/home/osboxes/PycharmProjects/Website-Ea-Group-Project/microblog/venv/lib/python3.6/site-packages/werkzeug/local.py", line 347, in __getattr__
    return getattr(self._get_current_object(), name)
  File "/home/osboxes/PycharmProjects/Website-Ea-Group-Project/microblog/venv/lib/python3.6/site-packages/werkzeug/local.py", line 306, in _get_current_object
    return self.__local()
  File "/home/osboxes/PycharmProjects/Website-Ea-Group-Project/microblog/venv/lib/python3.6/site-packages/flask_login/utils.py", line 26, in <lambda>
    current_user = LocalProxy(lambda: _get_user())
  File "/home/osboxes/PycharmProjects/Website-Ea-Group-Project/microblog/venv/lib/python3.6/site-packages/flask_login/utils.py", line 335, in _get_user
    current_app.login_manager._load_user()
  File "/home/osboxes/PycharmProjects/Website-Ea-Group-Project/microblog/venv/lib/python3.6/site-packages/flask_login/login_manager.py", line 359, in _load_user
    return self.reload_user()
  File "/home/osboxes/PycharmProjects/Website-Ea-Group-Project/microblog/venv/lib/python3.6/site-packages/flask_login/login_manager.py", line 321, in reload_user
    user = self.user_callback(user_id)
  File "/home/osboxes/PycharmProjects/Website-Ea-Group-Project/microblog/app/models.py", line 71, in load_user
    return User.query.get(int(id))
  File "/home/osboxes/PycharmProjects/Website-Ea-Group-Project/microblog/venv/lib/python3.6/site-packages/sqlalchemy/orm/query.py", line 887, in get
    ident, loading.load_on_pk_identity)
  File "/home/osboxes/PycharmProjects/Website-Ea-Group-Project/microblog/venv/lib/python3.6/site-packages/sqlalchemy/orm/query.py", line 962, in _get_impl
    return db_load_fn(self, primary_key_identity)
  File "/home/osboxes/PycharmProjects/Website-Ea-Group-Project/microblog/venv/lib/python3.6/site-packages/sqlalchemy/orm/loading.py", line 250, in load_on_pk_identity
    return q.one()
  File "/home/osboxes/PycharmProjects/Website-Ea-Group-Project/microblog/venv/lib/python3.6/site-packages/sqlalchemy/orm/query.py", line 2894, in one
    ret = self.one_or_none()
  File "/home/osboxes/PycharmProjects/Website-Ea-Group-Project/microblog/venv/lib/python3.6/site-packages/sqlalchemy/orm/query.py", line 2864, in one_or_none
    ret = list(self)
  File "/home/osboxes/PycharmProjects/Website-Ea-Group-Project/microblog/venv/lib/python3.6/site-packages/sqlalchemy/orm/query.py", line 2935, in __iter__
    return self._execute_and_instances(context)
  File "/home/osboxes/PycharmProjects/Website-Ea-Group-Project/microblog/venv/lib/python3.6/site-packages/sqlalchemy/orm/query.py", line 2958, in _execute_and_instances
    result = conn.execute(querycontext.statement, self._params)
  File "/home/osboxes/PycharmProjects/Website-Ea-Group-Project/microblog/venv/lib/python3.6/site-packages/sqlalchemy/engine/base.py", line 948, in execute
    return meth(self, multiparams, params)
  File "/home/osboxes/PycharmProjects/Website-Ea-Group-Project/microblog/venv/lib/python3.6/site-packages/sqlalchemy/sql/elements.py", line 269, in _execute_on_connection
    return connection._execute_clauseelement(self, multiparams, params)
  File "/home/osboxes/PycharmProjects/Website-Ea-Group-Project/microblog/venv/lib/python3.6/site-packages/sqlalchemy/engine/base.py", line 1060, in _execute_clauseelement
    compiled_sql, distilled_params
  File "/home/osboxes/PycharmProjects/Website-Ea-Group-Project/microblog/venv/lib/python3.6/site-packages/sqlalchemy/engine/base.py", line 1200, in _execute_context
    context)
  File "/home/osboxes/PycharmProjects/Website-Ea-Group-Project/microblog/venv/lib/python3.6/site-packages/sqlalchemy/engine/base.py", line 1413, in _handle_dbapi_exception
    exc_info
  File "/home/osboxes/PycharmProjects/Website-Ea-Group-Project/microblog/venv/lib/python3.6/site-packages/sqlalchemy/util/compat.py", line 203, in raise_from_cause
    reraise(type(exception), exception, tb=exc_tb, cause=cause)
  File "/home/osboxes/PycharmProjects/Website-Ea-Group-Project/microblog/venv/lib/python3.6/site-packages/sqlalchemy/util/compat.py", line 186, in reraise
    raise value.with_traceback(tb)
  File "/home/osboxes/PycharmProjects/Website-Ea-Group-Project/microblog/venv/lib/python3.6/site-packages/sqlalchemy/engine/base.py", line 1193, in _execute_context
    context)
  File "/home/osboxes/PycharmProjects/Website-Ea-Group-Project/microblog/venv/lib/python3.6/site-packages/sqlalchemy/engine/default.py", line 508, in do_execute
    cursor.execute(statement, parameters)
  File "/home/osboxes/PycharmProjects/Website-Ea-Group-Project/microblog/venv/lib/python3.6/site-packages/pymysql/cursors.py", line 170, in execute
    result = self._query(query)
  File "/home/osboxes/PycharmProjects/Website-Ea-Group-Project/microblog/venv/lib/python3.6/site-packages/pymysql/cursors.py", line 328, in _query
    conn.query(q)
  File "/home/osboxes/PycharmProjects/Website-Ea-Group-Project/microblog/venv/lib/python3.6/site-packages/pymysql/connections.py", line 516, in query
    self._affected_rows = self._read_query_result(unbuffered=unbuffered)
  File "/home/osboxes/PycharmProjects/Website-Ea-Group-Project/microblog/venv/lib/python3.6/site-packages/pymysql/connections.py", line 727, in _read_query_result
    result.read()
  File "/home/osboxes/PycharmProjects/Website-Ea-Group-Project/microblog/venv/lib/python3.6/site-packages/pymysql/connections.py", line 1066, in read
    first_packet = self.connection._read_packet()
  File "/home/osboxes/PycharmProjects/Website-Ea-Group-Project/microblog/venv/lib/python3.6/site-packages/pymysql/connections.py", line 683, in _read_packet
    packet.check_error()
  File "/home/osboxes/PycharmProjects/Website-Ea-Group-Project/microblog/venv/lib/python3.6/site-packages/pymysql/protocol.py", line 220, in check_error
    err.raise_mysql_exception(self._data)
  File "/home/osboxes/PycharmProjects/Website-Ea-Group-Project/microblog/venv/lib/python3.6/site-packages/pymysql/err.py", line 109, in raise_mysql_exception
    raise errorclass(errno, errval)
sqlalchemy.exc.ProgrammingError: (pymysql.err.ProgrammingError) (1146, "Table 'app.user' doesn't exist") [SQL: 'SELECT user.id AS user_id, user.first_name AS user_first_name, user.last_name AS user_last_name, user.username AS user_username, user.email AS user_email, user.phone AS user_phone, user.password_hash AS user_password_hash, user.gender AS user_gender, user.last_seen AS user_last_seen \nFROM user \nWHERE user.id = %(param_1)s'] [parameters: {'param_1': 0}] (Background on this error at: http://sqlalche.me/e/f405)
2020-04-29 23:58:02,060 INFO: Microblog startup [in /home/osboxes/PycharmProjects/Website-Ea-Group-Project/microblog/app/__init__.py:78]
